<?xml version="1.0" encoding="utf-8"?>
<robot
  name="robotic_arm_urdf">
  <link
    name="FIxed_plate">
    <inertial>
      <origin
        xyz="-0.0355492315280312 0.0355492315289991 0.0112338689642525"
        rpy="0 0 0" />
      <mass
        value="0.325739041943602" />
      <inertia
        ixx="0.00103876978477356"
        ixy="-1.3053571776551E-05"
        ixz="-2.691250829167E-15"
        iyy="0.00103876978455108"
        iyz="-1.51723471237219E-15"
        izz="0.00194709727851448" />
    </inertial>
    <visual>
      <origin
        xyz="0 0 0"
        rpy="0 0 0" />
      <geometry>
        <mesh
          filename="package://robotic_arm_urdf/meshes/FIxed_plate.STL" />
      </geometry>
      <material
        name="">
        <color
          rgba="0.792156862745098 0.819607843137255 0.933333333333333 1" />
      </material>
    </visual>
    <collision>
      <origin
        xyz="0 0 0"
        rpy="0 0 0" />
      <geometry>
        <mesh
          filename="package://robotic_arm_urdf/meshes/FIxed_plate.STL" />
      </geometry>
    </collision>
  </link>
  <link
    name="Base">
    <inertial>
      <origin
        xyz="-0.0172615520702472 0.00173059106799278 0.0154865918208336"
        rpy="0 0 0" />
      <mass
        value="1.89486895954733" />
      <inertia
        ixx="0.00465241432181342"
        ixy="-2.39407502824797E-05"
        ixz="6.77868812842936E-05"
        iyy="0.0037837347400817"
        iyz="-1.86673448437757E-06"
        izz="0.00619989444867366" />
    </inertial>
    <visual>
      <origin
        xyz="0 0 0"
        rpy="0 0 0" />
      <geometry>
        <mesh
          filename="package://robotic_arm_urdf/meshes/Base.STL" />
      </geometry>
      <material
        name="">
        <color
          rgba="1 0.949019607843137 0.909803921568627 1" />
      </material>
    </visual>
    <collision>
      <origin
        xyz="0 0 0"
        rpy="0 0 0" />
      <geometry>
        <mesh
          filename="package://robotic_arm_urdf/meshes/Base.STL" />
      </geometry>
    </collision>
  </link>
  <joint
    name="Base_joint"
    type="revolute">
    <origin
      xyz="-0.000869195529410005 0.000774746946535121 0.0750000020000001"
      rpy="0 0 0" />
    <parent
      link="FIxed_plate" />
    <child
      link="Base" />
    <axis
      xyz="0 0 1" />
    <limit
      lower="-3.142"
      upper="3.142"
      effort="400"
      velocity="2" />
  </joint>
  <link
    name="Shoulder">
    <inertial>
      <origin
        xyz="-0.000361876829587437 0.0131423339615002 -0.146450345830128"
        rpy="0 0 0" />
      <mass
        value="0.206135703604" />
      <inertia
        ixx="0.00079815276156277"
        ixy="7.777176168602E-07"
        ixz="-1.67147456303331E-06"
        iyy="0.000754963128939768"
        iyz="5.93275242987596E-05"
        izz="9.91599788840196E-05" />
    </inertial>
    <visual>
      <origin
        xyz="0 0 0"
        rpy="0 0 0" />
      <geometry>
        <mesh
          filename="package://robotic_arm_urdf/meshes/Shoulder.STL" />
      </geometry>
      <material
        name="">
        <color
          rgba="0.792156862745098 0.819607843137255 0.933333333333333 1" />
      </material>
    </visual>
    <collision>
      <origin
        xyz="0 0 0"
        rpy="0 0 0" />
      <geometry>
        <mesh
          filename="package://robotic_arm_urdf/meshes/Shoulder.STL" />
      </geometry>
    </collision>
  </link>
  <joint
    name="Shoulder_joint"
    type="revolute">
    <origin
      xyz="0.0447197560242002 -0.00112412203816992 0.073"
      rpy="3.14159265358979 0 3.14159265358979" />
    <parent
      link="Base" />
    <child
      link="Shoulder" />
    <axis
      xyz="0.999621046089309 0.0275275174201486 0" />
    <limit
      lower="-1.571"
      upper="1.571"
      effort="300"
      velocity="2" />
  </joint>
  <link
    name="Elbow">
    <inertial>
      <origin
        xyz="-0.00615064215020011 0.231940849174271 0.0202529590171407"
        rpy="0 0 0" />
      <mass
        value="1.17007641710888" />
      <inertia
        ixx="0.00223526150496956"
        ixy="-5.45831309078493E-06"
        ixz="2.61608936726327E-06"
        iyy="0.00243240447092899"
        iyz="-9.31620990988151E-05"
        izz="0.00378658118724182" />
    </inertial>
    <visual>
      <origin
        xyz="0 0 0"
        rpy="0 0 0" />
      <geometry>
        <mesh
          filename="package://robotic_arm_urdf/meshes/Elbow.STL" />
      </geometry>
      <material
        name="">
        <color
          rgba="0.792156862745098 0.819607843137255 0.933333333333333 1" />
      </material>
    </visual>
    <collision>
      <origin
        xyz="0 0 0"
        rpy="0 0 0" />
      <geometry>
        <mesh
          filename="package://robotic_arm_urdf/meshes/Elbow.STL" />
      </geometry>
    </collision>
  </link>
  <joint
    name="Elbow_joint"
    type="revolute">
    <origin
      xyz="-0.000682341576827228 0.0247782242594574 -0.36424259554965"
      rpy="0 0 0" />
    <parent
      link="Shoulder" />
    <child
      link="Elbow" />
    <axis
      xyz="-0.999621046088342 -0.0275275174552426 0" />
    <limit
      lower="-1.571"
      upper="1.571"
      effort="200"
      velocity="2" />
  </joint>
  <link
    name="Wrist_vertical">
    <inertial>
      <origin
        xyz="-0.000382753688242476 0.0138991335099079 0.00124824590327344"
        rpy="0 0 0" />
      <mass
        value="0.23033549720499" />
      <inertia
        ixx="8.68135745703536E-05"
        ixy="-4.99648408237074E-06"
        ixz="4.64108496955296E-08"
        iyy="0.000268115770317596"
        iyz="-1.68462893405136E-06"
        izz="0.000286874484620967" />
    </inertial>
    <visual>
      <origin
        xyz="0 0 0"
        rpy="0 0 0" />
      <geometry>
        <mesh
          filename="package://robotic_arm_urdf/meshes/Wrist_vertical.STL" />
      </geometry>
      <material
        name="">
        <color
          rgba="0.792156862745098 0.819607843137255 0.933333333333333 1" />
      </material>
    </visual>
    <collision>
      <origin
        xyz="0 0 0"
        rpy="0 0 0" />
      <geometry>
        <mesh
          filename="package://robotic_arm_urdf/meshes/Wrist_vertical.STL" />
      </geometry>
    </collision>
  </link>
  <joint
    name="Wrist_vertical_joint"
    type="revolute">
    <origin
      xyz="-0.0114424125784452 0.415514271147883 0.0373162827874605"
      rpy="0 0 0" />
    <parent
      link="Elbow" />
    <child
      link="Wrist_vertical" />
    <axis
      xyz="0.999621046088342 0.0275275174552392 0" />
    <limit
      lower="-4.712"
      upper="4.712"
      effort="100"
      velocity="2" />
  </joint>
  <link
    name="Wrist_rotate">
    <inertial>
      <origin
        xyz="-0.000741681505049496 0.0790718057517934 0.00720079404598062"
        rpy="0 0 0" />
      <mass
        value="0.330165609400149" />
      <inertia
        ixx="0.000258883847986465"
        ixy="-6.52789862310991E-05"
        ixz="-6.54935620068127E-06"
        iyy="0.000587879432240242"
        iyz="-1.8698217744701E-05"
        izz="0.000766196311553194" />
    </inertial>
    <visual>
      <origin
        xyz="0 0 0"
        rpy="0 0 0" />
      <geometry>
        <mesh
          filename="package://robotic_arm_urdf/meshes/Wrist_rotate.STL" />
      </geometry>
      <material
        name="">
        <color
          rgba="0.792156862745098 0.819607843137255 0.933333333333333 1" />
      </material>
    </visual>
    <collision>
      <origin
        xyz="0 0 0"
        rpy="0 0 0" />
      <geometry>
        <mesh
          filename="package://robotic_arm_urdf/meshes/Wrist_rotate.STL" />
      </geometry>
    </collision>
  </link>
  <joint
    name="Wrist_rotate_joint"
    type="revolute">
    <origin
      xyz="-0.00137289260615669 0.0498545619559456 0.00447731175889965"
      rpy="0 0 0" />
    <parent
      link="Wrist_vertical" />
    <child
      link="Wrist_rotate" />
    <axis
      xyz="0.0274172576374139 -0.995617124026799 -0.0894138486379424" />
    <limit
      lower="-3.142"
      upper="3.142"
      effort="100"
      velocity="2" />
  </joint>
  <link
    name="Gripper">
    <inertial>
      <origin
        xyz="0.00811651980572647 0.032809174371621 -0.00384137153551856"
        rpy="0 0 0" />
      <mass
        value="0.0388186179630637" />
      <inertia
        ixx="3.52038934993049E-05"
        ixy="-8.52223366530065E-08"
        ixz="1.40714485359173E-08"
        iyy="4.65934304491522E-06"
        iyz="3.59587138438163E-06"
        izz="3.18621067774847E-05" />
    </inertial>
    <visual>
      <origin
        xyz="0 0 0"
        rpy="0 0 0" />
      <geometry>
        <mesh
          filename="package://robotic_arm_urdf/meshes/Gripper.STL" />
      </geometry>
      <material
        name="">
        <color
          rgba="0.792156862745098 0.819607843137255 0.933333333333333 1" />
      </material>
    </visual>
    <collision>
      <origin
        xyz="0 0 0"
        rpy="0 0 0" />
      <geometry>
        <mesh
          filename="package://robotic_arm_urdf/meshes/Gripper.STL" />
      </geometry>
    </collision>
  </link>
  <joint
    name="Gripper_joint"
    type="prismatic">
    <origin
      xyz="-0.037934092087304 0.106065377723266 0.00961198872859703"
      rpy="3.14159265358979 0 3.14159265358979" />
    <parent
      link="Wrist_rotate" />
    <child
      link="Gripper" />
    <axis
      xyz="-0.999621046088342 0.0275275174552392 0" />
    <limit
      lower="0"
      upper="0.09"
      effort="50"
      velocity="0.06" />
  </joint>
</robot>
